---
url: /7227127412671160320
title: '异常堆栈日志的填充时机'
date: 2024-08-08T09:08:05+08:00
draft: false
summary: "记一次开发中的错误实践"
categories: [Java]
tags: ['top', 'Java基础', '异常', '错误实践']
---

<hr>

异常是Java中的一个重要机制，它会在程序出现非法情况的时候被抛出。但是每次抛出时，都需要 new 一个异常对象，所以就有了这次的错误实践。

我在异常类中提供了一些 `public static final` 的异常对象常量，刚开始还没发现问题，直到异常被抛出的时候。

这个时候抛出的异常不再携带正常的堆栈日志，而是只记录到了创建这个对象的时候。

问题复现代码如下：

```java
package versions.java8.exception.custom_exception.stacktrace;

import cn.hutool.core.exceptions.ExceptionUtil;

/**
 * 测试常量异常对象是否可以跟踪堆栈日志
 *
 * @author: xfdzcoder
 */
public class CustomExceptionStackTraceTest {

    private static final CustomException CUSTOM_EXCEPTION = new CustomException("抛出 静态常量 自定义异常");

    public static void main(String[] args) {
        testNew();
        testStaticFinal();
    }

    private static void testStaticFinal() {
        method1();
    }

    private static void method1() {
        try {
            throw CUSTOM_EXCEPTION;
        } catch (CustomException e) {
            System.out.println(ExceptionUtil.stacktraceToString(e));
        }
    }

    public static void testNew() {
        try {
            throw new CustomException("抛出 new 自定义异常");
        } catch (CustomException e) {
            System.out.println(ExceptionUtil.stacktraceToString(e));
        }
    }

}

```

执行结果如下：

```java
versions.java8.exception.custom_exception.stacktrace.CustomException: 抛出 new 自定义异常
	at versions.java8.exception.custom_exception.stacktrace.CustomExceptionStackTraceTest.testNew(CustomExceptionStackTraceTest.java:33)
	at versions.java8.exception.custom_exception.stacktrace.CustomExceptionStackTraceTest.main(CustomExceptionStackTraceTest.java:15)

versions.java8.exception.custom_exception.stacktrace.CustomException: 抛出 静态常量 自定义异常
	at versions.java8.exception.custom_exception.stacktrace.CustomExceptionStackTraceTest.<clinit>(CustomExceptionStackTraceTest.java:12)
```

可以看到，抛出的静态常量异常的堆栈日志只记录到了 `<clinit>` ，这是类在初始化的时候填充的。

随后就可以进行 debug 了，会发现堆栈日志的填充是在 `Throwable` 中的构造方法里面进行的。源码如下：

```java
    /**
	 * 使用指定的详细信息消息构造一个新的 throwable。原因未初始化，随后可能通过调用 initCause来初始化。
	 * 调用该 fillInStackTrace() 方法以在新创建的 throwable 中初始化堆栈跟踪数据。
	 *
	 * 参数：message – 详细消息。该方法将保存详细信息消息以供以后检索 getMessage() 。
     */
    public Throwable(String message) {
        fillInStackTrace();
        detailMessage = message;
    }

    /**
     * 填充执行堆栈跟踪。此方法在此 Throwable 对象中记录有关当前线程的堆栈帧的当前状态的信息。
     * 如果此 Throwable的堆栈跟踪 不可写，则调用此方法不起作用。
     *
     * 返回：对此实例的 Throwable 引用。
     * 另请参见：printStackTrace()
     */
    public synchronized Throwable fillInStackTrace() {
        if (stackTrace != null ||
            backtrace != null /* Out of protocol state */ ) {
            fillInStackTrace(0);
            stackTrace = UNASSIGNED_STACK;
        }
        return this;
    }

    private native Throwable fillInStackTrace(int dummy);
```

好了到这里就真相大白了，异常对象的 new 是无可避免的，如果手动调用 `fillInStackTrace` 的话，还会引发线程竞争导致日志打印出错的问题。